<mujoco model="quad_robo">
  <option iterations="50" timestep="0.001" solver="PGS" gravity="0 0 -9.81" />

  <compiler angle="radian" meshdir="meshes" eulerseq="zyx" autolimits="true" />

  <default>
    <joint limited="true" damping="0.01" armature="0.01" frictionloss="0.01" />
    <geom condim="4" contype="1" conaffinity="15" friction="0.9 0.2 0.2" solref="0.001 2" />
    <motor ctrllimited="true" />
    <equality solref="0.001 2" />
    <default class="visualgeom">
      <geom material="visualgeom" condim="1" contype="0" conaffinity="0" />
    </default>
  </default>

  <asset>
    <mesh name="body" file="body.STL" />
    <mesh name="camera" file="camera.STL" />
    <mesh name="back_right_thigh" file="back_right_thigh.STL" />
    <mesh name="back_right_leg" file="back_right_leg.STL" />
    <mesh name="back_right_shin" file="back_right_shin.STL" />
    <mesh name="back_left_thigh" file="back_left_thigh.STL" />
    <mesh name="back_left_leg" file="back_left_leg.STL" />
    <mesh name="back_left_shin" file="back_left_shin.STL" />
    <mesh name="front_left_thigh" file="front_left_thigh.STL" />
    <mesh name="front_left_leg" file="front_left_leg.STL" />
    <mesh name="front_left_shin" file="front_left_shin.STL" />
    <mesh name="front_right_thigh" file="front_right_thigh.STL" />
    <mesh name="front_right_leg" file="front_right_leg.STL" />
    <mesh name="front_right_shin" file="front_right_shin.STL" />
    <texture name="texplane" type="2d" builtin="checker" rgb1=".0 .0 .0" rgb2=".8 .8 .8" width="100" height="100" />
    <material name="matplane" reflectance="0." texture="texplane" texrepeat="1 1" texuniform="true" />
    <material name="visualgeom" rgba="0.5 0.9 0.2 1" />
  </asset>

  <worldbody>
    <light directional="true" diffuse="0.4 0.4 0.4" specular="0.1 0.1 0.1" pos="0 0 5.0" dir="0 0 -1" castshadow="false" />
    <light directional="true" diffuse="0.6 0.6 0.6" specular="0.2 0.2 0.2" pos="0 0 4" dir="0 0 -1" />
    <geom name="ground" type="plane" pos="0 0 0" size="100 100 0.001" quat="1 0 0 0" material="matplane" condim="3" conaffinity="15" />
    <camera name="fixed" pos="0 -3.0 0.5" xyaxes="1 0 0 0 0 1" />
    <camera name="track" mode="trackcom" pos="0 -3.0 0.5" xyaxes="1 0 0 0 0 1" />
    <body name="root" pos="0 0 1.0" quat="1 0 0 0">
      <freejoint name="root" />
      <site name="imu" size="0.01" pos="0 0 0" />
      <geom type="mesh" rgba="0 0.752941 0 1" mesh="body" contype="1" conaffinity="0" density="0" group="1" class="visualgeom" />
      <geom type="mesh" rgba="0 0.752941 0 1" mesh="body" />
      <geom pos="0.4 -0.005 0.095" quat="0.707107 0.707107 0 0" type="mesh" rgba="0 0 0 1" mesh="camera" contype="1" conaffinity="0" density="0" group="1" class="visualgeom" />
      <geom type="mesh" rgba="0 0 0 1" mesh="camera" pos="0.4 -0.005 0.095" quat="0.707107 0.707107 0 0" />
      <body name="back_right_thigh" pos="-0.24995 -0.18 0" quat="0 0 -0.709831 0.704372">
        <inertial pos="0.0629098 0 0.0554258" quat="0.993254 0 0.115957 0" mass="2.7702" diaginertia="0.0125596 0.0121647 0.00639203" />
        <joint name="back_right_thigh_joint" pos="0 0 0" axis="1 0 0" range="-3.14 3.14" actuatorfrcrange="-1000 1000" />
        <geom type="mesh" rgba="0.25098 0.25098 0.25098 1" mesh="back_right_thigh" contype="1" conaffinity="0" density="0" group="1" class="visualgeom" />
        <geom type="mesh" rgba="0.25098 0.25098 0.25098 1" mesh="back_right_thigh" />
        <body name="back_right_leg" pos="0.07005 0 0.070008" quat="-0.00392279 0.707097 0.00392277 0.707095">
          <inertial pos="0.0730353 -0.237418 6.51884e-09" quat="0.509262 0.490495 -0.509328 0.490563" mass="6.93817" diaginertia="0.145238 0.144942 0.0172124" />
          <joint name="back_right_leg_joint" pos="0 0 0" axis="1 0 0" range="-3.14 3.14" actuatorfrcrange="-1000 1000" />
          <geom type="mesh" rgba="0.501961 1 0.501961 1" mesh="back_right_leg" contype="1" conaffinity="0" density="0" group="1" class="visualgeom" />
          <geom type="mesh" rgba="0.501961 1 0.501961 1" mesh="back_right_leg" />
          <body name="back_right_shin" pos="0 -0.5 0" quat="0.00459773 0.999989 0 0">
            <inertial pos="0.0699917 0.206759 -2.45496e-07" quat="0.499992 0.499992 -0.500008 0.500008" mass="2.18909" diaginertia="0.0499442 0.0495545 0.00191161" />
            <joint name="back_right_shin_joint" pos="0 0 0" axis="1 0 0" range="-3.14 3.14" actuatorfrcrange="-1000 1000" />
            <geom type="mesh" rgba="0 0 0 1" mesh="back_right_shin" contype="1" conaffinity="0" density="0" group="1" class="visualgeom" />
            <geom type="mesh" rgba="0 0 0 1" mesh="back_right_shin" />
          </body>
        </body>
      </body>
      <body name="back_left_thigh" pos="-0.24995 0.18 0" quat="-2.62832e-06 -2.566e-06 0.698572 0.71554">
        <inertial pos="0.0629098 0 0.0554258" quat="0.993254 0 0.115957 0" mass="2.7702" diaginertia="0.0125596 0.0121647 0.00639203" />
        <joint name="back_left_thigh_joint" pos="0 0 0" axis="-1 0 0" range="-3.14 3.14" actuatorfrcrange="-1000 1000" />
        <geom type="mesh" rgba="0.25098 0.25098 0.25098 1" mesh="back_left_thigh" contype="1" conaffinity="0" density="0" group="1" class="visualgeom" />
        <geom type="mesh" rgba="0.25098 0.25098 0.25098 1" mesh="back_left_thigh" />
        <body name="back_left_leg" pos="0.07005 0 0.0700804" quat="0.707086 0.00546207 -0.707086 0.00546206">
          <inertial pos="0.0729632 -0.237418 -5.14056e-09" quat="0.509261 0.490494 -0.509329 0.490564" mass="6.93817" diaginertia="0.145238 0.144942 0.0172124" />
          <joint name="back_left_leg_joint" pos="0 0 0" axis="-1 0 0" range="-3.14 3.14" actuatorfrcrange="-1000 1000" />
          <geom type="mesh" rgba="0.501961 1 0.501961 1" mesh="back_left_leg" contype="1" conaffinity="0" density="0" group="1" class="visualgeom" />
          <geom type="mesh" rgba="0.501961 1 0.501961 1" mesh="back_left_leg" />
          <body name="back_left_shin" pos="0 -0.5 0" quat="0.00510775 -0.999987 0 0">
            <inertial pos="0.0699198 0.206759 2.62203e-07" quat="0.5 0.5 -0.5 0.5" mass="2.1891" diaginertia="0.0499443 0.0495545 0.00191162" />
            <joint name="back_left_shin_joint" pos="0 0 0" axis="-1 0 0" range="-3.14 3.14" actuatorfrcrange="-1000 1000" />
            <geom type="mesh" rgba="0 0 0 1" mesh="back_left_shin" contype="1" conaffinity="0" density="0" group="1" class="visualgeom" />
            <geom type="mesh" rgba="0 0 0 1" mesh="back_left_shin" />
          </body>
        </body>
      </body>
      <body name="front_left_thigh" pos="0.24995 0.18 0" quat="0.717563 -0.696494 0 0">
        <inertial pos="0.0629098 0 0.0554258" quat="0.993254 0 0.115957 0" mass="2.7702" diaginertia="0.0125596 0.0121647 0.00639203" />
        <joint name="front_left_thigh_joint" pos="0 0 0" axis="1 0 0" range="-3.14 3.14" actuatorfrcrange="-1000 1000" />
        <geom type="mesh" rgba="0.25098 0.25098 0.25098 1" mesh="front_left_thigh" contype="1" conaffinity="0" density="0" group="1" class="visualgeom" />
        <geom type="mesh" rgba="0.25098 0.25098 0.25098 1" mesh="front_left_thigh" />
        <body name="front_left_leg" pos="0.07005 0 0.0701239" quat="-0.00317285 -0.7071 0.00317286 -0.7071">
          <inertial pos="0.0729198 -0.237418 3.33459e-09" quat="0.509262 0.490495 -0.509328 0.490564" mass="6.93817" diaginertia="0.145238 0.144942 0.0172124" />
          <joint name="front_left_leg_joint" pos="0 0 0" axis="-1 0 0" range="-3.14 3.14" actuatorfrcrange="-1000 1000" />
          <geom type="mesh" rgba="0.501961 1 0.501961 1" mesh="front_left_leg" contype="1" conaffinity="0" density="0" group="1" class="visualgeom" />
          <geom type="mesh" rgba="0.501961 1 0.501961 1" mesh="front_left_leg" />
          <body name="front_left_shin" pos="0 -0.5 0" quat="0.0117301 -0.999931 0 0">
            <inertial pos="0.0698764 0.206759 1.34054e-07" quat="0.5 0.5 -0.5 0.5" mass="2.18909" diaginertia="0.0499442 0.0495545 0.00191161" />
            <joint name="front_left_shin_joint" pos="0 0 0" axis="-1 0 0" range="-3.14 3.14" actuatorfrcrange="-1000 1000" />
            <geom type="mesh" rgba="0 0 0 1" mesh="front_left_shin" contype="1" conaffinity="0" density="0" group="1" class="visualgeom" />
            <geom type="mesh" rgba="0 0 0 1" mesh="front_left_shin" />
          </body>
        </body>
      </body>
      <body name="front_right_thigh" pos="0.24995 -0.18 0" quat="0.705082 0.709126 0 0">
        <inertial pos="0.0629098 0 0.0554258" quat="0.993254 0 0.115957 0" mass="2.7702" diaginertia="0.0125596 0.0121647 0.00639203" />
        <joint name="front_right_thigh_joint" pos="0 0 0" axis="-1 0 0" range="-3.14 3.14" actuatorfrcrange="-1000 1000" />
        <geom type="mesh" rgba="0.25098 0.25098 0.25098 1" mesh="front_right_thigh" contype="1" conaffinity="0" density="0" group="1" class="visualgeom" />
        <geom type="mesh" rgba="0.25098 0.25098 0.25098 1" mesh="front_right_thigh" />
        <body name="front_right_leg" pos="0.07005 0 0.0700046" quat="0.707082 0.00589294 -0.707082 0.00589293">
          <inertial pos="0.073039 -0.237418 -3.69308e-09" quat="0.509261 0.490494 -0.509328 0.490564" mass="6.93817" diaginertia="0.145238 0.144942 0.0172124" />
          <joint name="front_right_leg_joint" pos="0 0 0" axis="1 0 0" range="-3.14 3.14" actuatorfrcrange="-1000 1000" />
          <geom type="mesh" rgba="0.501961 1 0.501961 1" mesh="front_right_leg" contype="1" conaffinity="0" density="0" group="1" class="visualgeom" />
          <geom type="mesh" rgba="0.501961 1 0.501961 1" mesh="front_right_leg" />
          <body name="front_right_shin" pos="0 -0.5 0" quat="0.0155385 0.999879 0 0">
            <inertial pos="0.0699954 0.206759 -1.74081e-07" quat="0.499992 0.499992 -0.500008 0.500008" mass="2.18909" diaginertia="0.0499442 0.0495545 0.00191161" />
            <joint name="front_right_shin_joint" pos="0 0 0" axis="1 0 0" range="-3.14 3.14" actuatorfrcrange="-1000 1000" />
            <geom type="mesh" rgba="0 0 0 1" mesh="front_right_shin" contype="1" conaffinity="0" density="0" group="1" class="visualgeom" />
            <geom type="mesh" rgba="0 0 0 1" mesh="front_right_shin" />
          </body>
        </body>
      </body>
    </body>
  </worldbody>

  <actuator>
    <motor name="back_right_thigh_joint" joint="back_right_thigh_joint" ctrllimited="true" ctrlrange="-1000 1000" gear="1" />
    <motor name="back_right_leg_joint" joint="back_right_leg_joint" ctrllimited="true" ctrlrange="-1000 1000" gear="1" />
    <motor name="back_right_shin_joint" joint="back_right_shin_joint" ctrllimited="true" ctrlrange="-1000 1000" gear="1" />
    <motor name="back_left_thigh_joint" joint="back_left_thigh_joint" ctrllimited="true" ctrlrange="-1000 1000" gear="1" />
    <motor name="back_left_leg_joint" joint="back_left_leg_joint" ctrllimited="true" ctrlrange="-1000 1000" gear="1" />
    <motor name="back_left_shin_joint" joint="back_left_shin_joint" ctrllimited="true" ctrlrange="-1000 1000" gear="1" />
    <motor name="front_left_thigh_joint" joint="front_left_thigh_joint" ctrllimited="true" ctrlrange="-1000 1000" gear="1" />
    <motor name="front_left_leg_joint" joint="front_left_leg_joint" ctrllimited="true" ctrlrange="-1000 1000" gear="1" />
    <motor name="front_left_shin_joint" joint="front_left_shin_joint" ctrllimited="true" ctrlrange="-1000 1000" gear="1" />
    <motor name="front_right_thigh_joint" joint="front_right_thigh_joint" ctrllimited="true" ctrlrange="-1000 1000" gear="1" />
    <motor name="front_right_leg_joint" joint="front_right_leg_joint" ctrllimited="true" ctrlrange="-1000 1000" gear="1" />
    <motor name="front_right_shin_joint" joint="front_right_shin_joint" ctrllimited="true" ctrlrange="-1000 1000" gear="1" />
  </actuator>

  <sensor>
    <actuatorpos name="back_right_thigh_joint_p" actuator="back_right_thigh_joint" />
    <actuatorvel name="back_right_thigh_joint_v" actuator="back_right_thigh_joint" />
    <actuatorfrc name="back_right_thigh_joint_f" actuator="back_right_thigh_joint" noise="0.001" />
    <actuatorpos name="back_right_leg_joint_p" actuator="back_right_leg_joint" />
    <actuatorvel name="back_right_leg_joint_v" actuator="back_right_leg_joint" />
    <actuatorfrc name="back_right_leg_joint_f" actuator="back_right_leg_joint" noise="0.001" />
    <actuatorpos name="back_right_shin_joint_p" actuator="back_right_shin_joint" />
    <actuatorvel name="back_right_shin_joint_v" actuator="back_right_shin_joint" />
    <actuatorfrc name="back_right_shin_joint_f" actuator="back_right_shin_joint" noise="0.001" />
    <actuatorpos name="back_left_thigh_joint_p" actuator="back_left_thigh_joint" />
    <actuatorvel name="back_left_thigh_joint_v" actuator="back_left_thigh_joint" />
    <actuatorfrc name="back_left_thigh_joint_f" actuator="back_left_thigh_joint" noise="0.001" />
    <actuatorpos name="back_left_leg_joint_p" actuator="back_left_leg_joint" />
    <actuatorvel name="back_left_leg_joint_v" actuator="back_left_leg_joint" />
    <actuatorfrc name="back_left_leg_joint_f" actuator="back_left_leg_joint" noise="0.001" />
    <actuatorpos name="back_left_shin_joint_p" actuator="back_left_shin_joint" />
    <actuatorvel name="back_left_shin_joint_v" actuator="back_left_shin_joint" />
    <actuatorfrc name="back_left_shin_joint_f" actuator="back_left_shin_joint" noise="0.001" />
    <actuatorpos name="front_left_thigh_joint_p" actuator="front_left_thigh_joint" />
    <actuatorvel name="front_left_thigh_joint_v" actuator="front_left_thigh_joint" />
    <actuatorfrc name="front_left_thigh_joint_f" actuator="front_left_thigh_joint" noise="0.001" />
    <actuatorpos name="front_left_leg_joint_p" actuator="front_left_leg_joint" />
    <actuatorvel name="front_left_leg_joint_v" actuator="front_left_leg_joint" />
    <actuatorfrc name="front_left_leg_joint_f" actuator="front_left_leg_joint" noise="0.001" />
    <actuatorpos name="front_left_shin_joint_p" actuator="front_left_shin_joint" />
    <actuatorvel name="front_left_shin_joint_v" actuator="front_left_shin_joint" />
    <actuatorfrc name="front_left_shin_joint_f" actuator="front_left_shin_joint" noise="0.001" />
    <actuatorpos name="front_right_thigh_joint_p" actuator="front_right_thigh_joint" />
    <actuatorvel name="front_right_thigh_joint_v" actuator="front_right_thigh_joint" />
    <actuatorfrc name="front_right_thigh_joint_f" actuator="front_right_thigh_joint" noise="0.001" />
    <actuatorpos name="front_right_leg_joint_p" actuator="front_right_leg_joint" />
    <actuatorvel name="front_right_leg_joint_v" actuator="front_right_leg_joint" />
    <actuatorfrc name="front_right_leg_joint_f" actuator="front_right_leg_joint" noise="0.001" />
    <actuatorpos name="front_right_shin_joint_p" actuator="front_right_shin_joint" />
    <actuatorvel name="front_right_shin_joint_v" actuator="front_right_shin_joint" />
    <actuatorfrc name="front_right_shin_joint_f" actuator="front_right_shin_joint" noise="0.001" />
    <framequat name="orientation" objtype="site" noise="0.001" objname="imu" />
    <gyro name="angular-velocity" site="imu" noise="0.005" cutoff="34.9" />
  </sensor>
</mujoco>